Workbook

Sheet Export Summary
B3: This document was exported from Numbers. Each table was converted to an Excel worksheet. All other objects on each Numbers sheet were placed on separate worksheets. Please be aware that formula calculations may differ in Excel.
B7: Numbers Sheet Name | C7: Numbers Table Name | D7: Excel Worksheet Name
B9: Info
C10: Table 1 | D10: Info
B11: Giocatori
C12: Table 1 | D12: Giocatori
B13: Squadre
C14: Table 1 | D14: Squadre
B15: Ballottaggi
C16: Table 1 | D16: Ballottaggi
B17: Piazzati
C18: Table 1 | D18: Piazzati
B19: Note
C20: Table 1 | D20: Note
B21: PuntiChiave
C22: Table 1 | D22: PuntiChiave

Sheet Info
A1: Guida all'Asta 26/27
A4: Guida aggiornata al | B4: 18/08/26 (data indicata dal sito)
A5: Data estrazione | B5: 18/08/2026 09:39 (ora locale del server)
A6: Squadre estratte | B6: {=COUNTA('Squadre'!A4:A100)} -> 20
A7: Giocatori estratti | B7: {=COUNTA('Giocatori'!C2:C505)} -> 504
A9: FOGLI
A10: Giocatori | B10: Rosa completa di ogni squadra con statistiche e tutti i flag (titolare, rigorista, ballottaggio, valorizzato...)
A11: Squadre | B11: Una riga per squadra: modulo, allenatore, valutazione attacco/difesa, XI titolare, punti chiave, schema ruoli
A12: Ballottaggi | B12: Tutti i duelli di formazione con le percentuali
A13: Piazzati | B13: Gerarchie di rigori, punizioni e calci d'angolo
A14: Note | B14: Valorizzati, penalizzati, nomi nascosti e giovani con le relative motivazioni
A15: PuntiChiave | B15: I punti chiave tattici di ogni allenatore, uno per riga
A17: LEGENDA COLONNE
A18: Ruolo | B18: P = portiere, D = difensore, C = centrocampista, A = attaccante (ruoli Classic)
A19: Titolarità | B19: Probabilità di essere titolare stimata (95%, 75%, 50%, 25%, 1%)
A20: MV | B20: Media voto della scorsa stagione. 0 = nessun dato disponibile (es. nuovi acquisti dall'estero)
A21: FMV | B21: Fantamedia voto della scorsa stagione. 0 = nessun dato disponibile
A22: PMA | B22: Percentuale media d'asta: quota del budget spesa in media per il giocatore. Valore dinamico: è una fotografia del momento dell'estrazione, cambia nel tempo
A23: Attacco / Difesa | B23: Valutazione della squadra in stelle su 5 (mezze stelle incluse)
A24: Ruoli chiave | B24: Schema dei ruoli Mantra del modulo tipo, dall'attacco al portiere
A25: Ballottaggio | B25: Percentuali e avversari nel duello per il posto da titolare
A27: NOTE
A28: Dati mancanti | B28: Nella sezione "Penalizzati" del Bologna il sito mostra una nota senza giocatore associato: è riportata con ruolo e nome vuoti
A29: Percentuali ballottaggi | B29: Nei ballottaggi a 3 il sito espone solo la percentuale del primo e dell'ultimo giocatore
A30: Ballottaggio Frosinone | B30: Masini - Koutsoupias: il sito non mostra le percentuali

Sheet Giocatori
A1: Squadra | B1: Ruolo | C1: Giocatore | D1: Titolarità | E1: MV | F1: FMV | G1: PMA | H1: Titolare XI | I1: Rigorista | J1: Punizioni | K1: Corner | L1: Ballottaggio | M1: Valorizzato | N1: Penalizzato | O1: Nome nascosto | P1: Giovane | Q1: Note guida
A2: Atalanta | B2: P | C2: Carnesecchi | D2: 0.95 | E2: 6.36 | F2: 5.58 | G2: 0.066 | H2: Sì
A3: Atalanta | B3: P | C3: Sportiello | D3: 0.01 | E3: 5.5 | F3: 4.5 | G3: 0.002
A4: Atalanta | B4: P | C4: Vismara | D4: 0.01 | E4: 0 | F4: 0 | G4: 0.002
A5: Atalanta | B5: D | C5: Bernasconi | D5: 0.95 | E5: 6.09 | F5: 6.16 | G5: 0.01 | H5: Sì | K5: 3 | L5: 51% vs Ahanor | P5: Sì | Q5: Giovane: Esterno equilibrato in entrambe le fasi
A6: Atalanta | B6: D | C6: Scalvini | D6: 0.95 | E6: 6.06 | F6: 6.44 | G6: 0.012 | H6: Sì | M6: Sì | Q6: Valorizzato: Difesa di Sarri solida
A7: Atalanta | B7: D | C7: Kristensen T. | D7: 0.75 | E7: 5.98 | F7: 6.23 | G7: 0.006 | H7: Sì | L7: 55% vs Kolasinac
A8: Atalanta | B8: D | C8: Zappacosta | D8: 0.75 | E8: 6.06 | F8: 6.3 | G8: 0.01 | H8: Sì | L8: 55% vs Bellanova
A9: Atalanta | B9: D | C9: Ahanor | D9: 0.5 | E9: 5.79 | F9: 5.69 | G9: 0.002 | L9: 49% vs Bernasconi
A10: Atalanta | B10: D | C10: Bellanova | D10: 0.5 | E10: 5.82 | F10: 5.82 | G10: 0.004 | L10: 45% vs Zappacosta
A11: Atalanta | B11: D | C11: Hien | D11: 0.5 | E11: 5.91 | F11: 5.86 | G11: 0.002
A12: Atalanta | B12: D | C12: Kolasinac | D12: 0.5 | E12: 6.03 | F12: 5.94 | G12: 0.002 | L12: 45% vs Kristensen T.
A13: Atalanta | B13: D | C13: Kossounou | D13: 0.25 | E13: 5.94 | F13: 6.1 | G13: 0.002 | N13: Sì | Q13: Penalizzato: Parte indietro nelle gerarchie del mister
A14: Atalanta | B14: C | C14: Ederson D.s. | D14: 0.95 | E14: 6.25 | F14: 6.43 | G14: 0.027 | H14: Sì | I14: 3
A15: Atalanta | B15: C | C15: De Roon | D15: 0.5 | E15: 5.97 | F15: 6 | G15: 0.002 | L15: 49% vs Gaetano | N15: Sì | Q15: Penalizzato: Con Sarri posizionamento più arretrato
A16: Atalanta | B16: C | C16: Gaetano | D16: 0.5 | E16: 6.06 | F16: 6.31 | G16: 0.004 | H16: Sì | J16: 2 | K16: 2 | L16: 51% vs De Roon
A17: Atalanta | B17: C | C17: Pasalic | D17: 0.5 | E17: 5.94 | F17: 6.28 | G17: 0.002 | L17: 49% vs Samardzic
A18: Atalanta | B18: C | C18: Samardzic | D18: 0.5 | E18: 5.93 | F18: 6.29 | G18: 0.038 | H18: Sì | I18: 2 | J18: 1 | K18: 1 | L18: 51% vs Pasalic | O18: Sì | Q18: Nome nascosto: Sarri può rigenerarlo
A19: Atalanta | B19: C | C19: Zalewski | D19: 0.5 | E19: 6.1 | F19: 6.41 | G19: 0.002
A20: Atalanta | B20: C | C20: Sulemana I. | D20: 0.25 | E20: 5.69 | F20: 5.77 | G20: 0.002
A21: Atalanta | B21: A | C21: De Ketelaere | D21: 0.95 | E21: 6.21 | F21: 6.6 | G21: 0.066 | H21: Sì
A22: Atalanta | B22: A | C22: Raspadori | D22: 0.75 | E22: 6.12 | F22: 6.89 | G22: 0.038 | H22: Sì | M22: Sì | Q22: Valorizzato: Adattabile anche al centro; Esterni di Sarri prolifici; Rotazioni elevate nel suo ruolo
A23: Atalanta | B23: A | C23: Krstovic | D23: 0.5 | E23: 6.16 | F23: 7.19 | G23: 0.064 | L23: 49% vs Scamacca
A24: Atalanta | B24: A | C24: Scamacca | D24: 0.5 | E24: 6.18 | F24: 7.54 | G24: 0.11 | H24: Sì | I24: 1 | L24: 51% vs Krstovic
A25: Atalanta | B25: A | C25: Sulemana K. | D25: 0.01 | E25: 6 | F25: 6.24 | G25: 0.002
A26: Bologna | B26: P | C26: Skorupski | D26: 0.75 | E26: 6.19 | F26: 5.27 | G26: 0.014 | H26: Sì
A27: Bologna | B27: P | C27: Pessina Mas. | D27: 0.25 | E27: 6.13 | F27: 5.63 | G27: 0.002
A28: Bologna | B28: P | C28: Happonen | D28: 0.01 | E28: 0 | F28: 0 | G28: 0.002
A29: Bologna | B29: D | C29: Miranda J. | D29: 0.95 | E29: 6 | F29: 6.1 | G29: 0.011 | H29: Sì | K29: 3
A30: Bologna | B30: D | C30: Heggem | D30: 0.5 | E30: 5.84 | F30: 5.8 | G30: 0.002 | H30: Sì
A31: Bologna | B31: D | C31: Vitik | D31: 0.5 | E31: 5.94 | F31: 5.86 | G31: 0.002 | H31: Sì
A32: Bologna | B32: D | C32: Zortea | D32: 0.5 | E32: 5.86 | F32: 5.9 | G32: 0.004 | H32: Sì | L32: 51% vs Holm
A33: Bologna | B33: D | C33: Alhassane | D33: 0.25 | E33: 0 | F33: 0
A34: Bologna | B34: D | C34: Holm | D34: 0.25 | E34: 6.09 | F34: 6.43 | G34: 0.002 | L34: 49% vs Zortea
A35: Bologna | B35: D | C35: Casale | D35: 0.01 | E35: 5.65 | F35: 5.65
A36: Bologna | B36: D | C36: De Silvestri | D36: 0.01 | E36: 6.05 | F36: 5.95 | G36: 0.002
A37: Bologna | B37: D | C37: Helland | D37: 0.01 | E37: 5.5 | F37: 5.33 | G37: 0.002
A38: Bologna | B38: C | C38: Orsolini | D38: 0.95 | E38: 6.06 | F38: 6.77 | G38: 0.122 | H38: Sì | I38: 1 | J38: 1 | K38: 1 | M38: Sì | Q38: Valorizzato: Perno offensivo del gioco del mister; Maggiore minutaggio rispetto all'anno scorso
A39: Bologna | B39: C | C39: Pobega | D39: 0.75 | E39: 5.83 | F39: 6.18 | G39: 0.002 | H39: Sì | L39: 55% vs Moro N.
A40: Bologna | B40: C | C40: Rowe | D40: 0.75 | E40: 6.2 | F40: 6.59 | G40: 0.04 | H40: Sì | M40: Sì | Q40: Valorizzato: Caratteristiche in linea con gli esterni del mister; Poca concorrenza
...

Sheet Squadre
A1: Guida all'Asta — Panoramica squadre (Classic)
A3: Squadra | B3: Modulo | C3: Allenatore | D3: Attacco (0-5) | E3: Difesa (0-5) | F3: N. giocatori | G3: Titolari 95% | H3: XI titolare | I3: Punti chiave | J3: Ruoli chiave (schema)
A4: Atalanta | B4: 4-3-3 | C4: M. Sarri | D4: 4 | E4: 4 | F4: {=COUNTIF('Giocatori'!$A$2:$A$505,$A4)} -> 24 | G4: {=_xlfn.COUNTIFS('Giocatori'!$A$2:$A$505,$A4,'Giocatori'!$D$2:$D$505,">=0.95")} -> 0 | H4: Scamacca - Raspadori - De Ketelaere - Ederson D.S. - Gaetano - Samardzic - Bernasconi - Kristensen T. - Scalvini - Zappacosta - Carnesecchi | I4: Valorizzazione esterni d'attacco • Solidità difensiva • Scarso impiego del turnover • Scarsa libertà ai terzini | J4: W Pc W C M C Ds Dc Dc Dd Por
A5: Bologna | B5: 4-3-3 | C5: D. Tedesco | D5: 4 | E5: 3.5 | F5: {=COUNTIF('Giocatori'!$A$2:$A$505,$A5)} -> 24 | G5: {=_xlfn.COUNTIFS('Giocatori'!$A$2:$A$505,$A5,'Giocatori'!$D$2:$D$505,">=0.95")} -> 0 | H5: Dovbyk - Rowe - Orsolini - Ferguson - Pobega - Bernardeschi - Miranda J. - Heggem - Vitik - Zortea - Skorupski | I5: Valorizzazione esterni d'attacco • Adattamento Serie A • Sistema di gioco molto elaborato | J5: W Pc W C M C Ds Dc Dc Dd Por
A6: Cagliari | B6: 4-3-3 | C6: F. Pisacane | D6: 2.5 | E6: 2.5 | F6: {=COUNTIF('Giocatori'!$A$2:$A$505,$A6)} -> 27 | G6: {=_xlfn.COUNTIFS('Giocatori'!$A$2:$A$505,$A6,'Giocatori'!$D$2:$D$505,">=0.95")} -> 0 | H6: Kevin Carlos - Fazzini - Maldini - Romano - Winks - Adopo - Obert - Rodriguez Ju. - Mina - Zè Pedro - Caprile | I6: Valorizzazione giovani • Solidità difensiva • Attacco poco prolifico | J6: W Pc W C M C Ds Dc Dc Dd Por
A7: Como | B7: 4-2-3-1 | C7: C. Fabregas | D7: 5 | E7: 4.5 | F7: {=COUNTIF('Giocatori'!$A$2:$A$505,$A7)} -> 29 | G7: {=_xlfn.COUNTIFS('Giocatori'!$A$2:$A$505,$A7,'Giocatori'!$D$2:$D$505,">=0.95")} -> 0 | H7: Douvikas - Baturina - Paz N. - Diao - Da Cunha - Perrone - Valle - Chalobah T. - Ramon - Couto - Butez | I7: Valorizzazione giovani • Solidità difensiva • Manovra fluida in fase offensiva | J7: Pc W T W M M Ds Dc Dc Dd Por
A8: Fiorentina | B8: 4-3-2-1 | C8: F. Grosso | D8: 3 | E8: 3 | F8: {=COUNTIF('Giocatori'!$A$2:$A$505,$A8)} -> 23 | G8: {=_xlfn.COUNTIFS('Giocatori'!$A$2:$A$505,$A8,'Giocatori'!$D$2:$D$505,">=0.95")} -> 0 | H8: Kean - Mastantuono - Atta - Ndour - Fagioli - Oulai - Valdepenas - Viery - Dragusin - Jimenez A. - De Gea | I8: Valorizzazione esterni d'attacco • Importanza mezzali • Difesa poco solida • Fatica contro squadre chiuse | J8: Pc T T C M C Ds Dc Dc Dd Por
A9: Frosinone | B9: 4-3-3 | C9: M. Alvini | D9: 2.5 | E9: 2 | F9: {=COUNTIF('Giocatori'!$A$2:$A$505,$A9)} -> 30 | G9: {=_xlfn.COUNTIFS('Giocatori'!$A$2:$A$505,$A9,'Giocatori'!$D$2:$D$505,">=0.95")} -> 0 | H9: Raimondo - Kvernadze - Ghedjemis - Masini - Grillitsch - Schmid - Terzic - Monterisi - Akpoguma - Oyono A. - Palmisani | I9: Importanza esterni d'attacco • Difensori potrebbero soffrire l'adattamento in serie A • Sfrutta bene i calci piazzati | J9: W Pc W C M C Ds Dc Dc Dd Por
A10: Genoa | B10: 3-4-2-1 | C10: D. De Rossi | D10: 3 | E10: 3 | F10: {=COUNTIF('Giocatori'!$A$2:$A$505,$A10)} -> 25 | G10: {=_xlfn.COUNTIFS('Giocatori'!$A$2:$A$505,$A10,'Giocatori'!$D$2:$D$505,">=0.95")} -> 0 | H10: Colombo - Vitinha O. - Baldanzi - Frendrup - Sow - Mitaj - Norton-Cuffy - Vasquez - Ostigard - Marcandalli - Bijlow | I10: Compattezza difensiva • Valorizzazione esterni bassi • Difficoltà dal punto di vista realizzativo | J10: Pc T T E C C E B Dc Dc Por
A11: Inter | B11: 3-5-2 | C11: C. Chivu | D11: 5 | E11: 5 | F11: {=COUNTIF('Giocatori'!$A$2:$A$505,$A11)} -> 23 | G11: {=_xlfn.COUNTIFS('Giocatori'!$A$2:$A$505,$A11,'Giocatori'!$D$2:$D$505,">=0.95")} -> 0 | H11: Thuram - Martinez L. - Zielinski - Calhanoglu - Barella - Dimarco - Spence - Bastoni - Stones - Akanji - Martinez Jo. | I11: Valorizzazione esterni • Transizione offensiva veloce e coordinata • Fase difensiva ordinata e organizzata | J11: Pc Pc E C M C E B Dc Dc Por
A12: Juventus | B12: 4-2-3-1 | C12: L. Spalletti | D12: 4.5 | E12: 4.5 | F12: {=COUNTIF('Giocatori'!$A$2:$A$505,$A12)} -> 27 | G12: {=_xlfn.COUNTIFS('Giocatori'!$A$2:$A$505,$A12,'Giocatori'!$D$2:$D$505,">=0.95")} -> 0 | H12: Kolo Muani - Yildiz - McKennie - Alajbegovic - Locatelli - Thuram K. - Cambiaso - Lucumì - Bremer - Kalulu - Di Gregorio | I12: Valorizzazione esterni offesivi • Solidità difensiva • Interpreti inadatti ad un giro palla veloce | J12: Pc W T W M M Ds Dc Dc Dd Por
A13: Lazio | B13: 4-3-3 | C13: G. Gattuso | D13: 3.5 | E13: 4 | F13: {=COUNTIF('Giocatori'!$A$2:$A$505,$A13)} -> 26 | G13: {=_xlfn.COUNTIFS('Giocatori'!$A$2:$A$505,$A13,'Giocatori'!$D$2:$D$505,">=0.95")} -> 0 | H13: Noslin - Zaccagni - Isaksen - Frattesi - Rovella - Taylor K. - Pedraza - Romagnoli - Doekhi - Marusic - Mandas | I13: Punta centrale riferimento principale • Gioco aggressivo, cartellini e falli elevati • Esterni di difesa propositivi | J13: W Pc W C M C Ds Dc Dc Dd Por
A14: Lecce | B14: 4-3-3 | C14: E. Di Francesco | D14: 2 | E14: 2.5 | F14: {=COUNTIF('Giocatori'!$A$2:$A$505,$A14)} -> 21 | G14: {=_xlfn.COUNTIFS('Giocatori'!$A$2:$A$505,$A14,'Giocatori'!$D$2:$D$505,">=0.95")} -> 0 | H14: Geubbels - N'Dri - Pierotti - Gandelman - Ngom - Coulibaly L. - Gallo - Gaspar K. - Tiago Gabriel - Veiga D. - Falcone | I14: Valorizzazione esterni d'attacco • Squadra poco prolifica per i bonus • Difesa aggressiva e propensa ai cartellini | J14: W Pc W C M C Ds Dc Dc Dd Por
A15: Milan | B15: 3-4-2-1 | C15: R. Amorim | D15: 4.5 | E15: 4.5 | F15: {=COUNTIF('Giocatori'!$A$2:$A$505,$A15)} -> 27 | G15: {=_xlfn.COUNTIFS('Giocatori'!$A$2:$A$505,$A15,'Giocatori'!$D$2:$D$505,">=0.95")} -> 0 | H15: Ramos G. - Leao - Pulisic - Modric - Rabiot - Bartesaghi - Saelemaekers - Pavlovic - Gabbia - Gila - Maignan | I15: Trequartisti ed esterni mobili in fase offensiva • Rigidità del sistema di gioco • Dipendenza da un attaccante fisico | J15: Pc T T E C C E B Dc Dc Por
... A23: Venezia | B23: 3-5-2 | C23: G. Stroppa | D23: 2.5 | E23: 2 | F23: {=COUNTIF('Giocatori'!$A$2:$A$505,$A23)} -> 27 | G23: {=_xlfn.COUNTIFS('Giocatori'!$A$2:$A$505,$A23,'Giocatori'!$D$2:$D$505,">=0.95")} -> 0 | H23: Yeboah J. - Adams A. - Sohm - Busio - Basic - Haps - Correia T. - Moreno M. - Bella-Kotchap - Schingtienne - Stankovic F. | I23: Gioco costante sugli esterni • Costruzione dal basso ossessiva • Interpreti del suo gioco potrebbero faticare in serie A | J23: Pc Pc E C M C E B Dc Dc Por

Sheet Ballottaggi
A1: Squadra | B1: Ruoli | C1: Giocatore 1 | D1: % 1 | E1: Giocatore 2 | F1: Giocatore 3 | G1: % ultimo
A2: Atalanta | B2: A/A | C2: Scamacca | D2: 0.51 | E2: Krstovic | G2: 0.49
A3: Atalanta | B3: C/C | C3: Gaetano | D3: 0.51 | E3: De Roon | G3: 0.49
A4: Atalanta | B4: D/D | C4: Zappacosta | D4: 0.55 | E4: Bellanova | G4: 0.45
A5: Atalanta | B5: D/D | C5: Kristensen T. | D5: 0.55 | E5: Kolasinac | G5: 0.45
A6: Atalanta | B6: C/C | C6: Samardzic | D6: 0.51 | E6: Pasalic | G6: 0.49
A7: Atalanta | B7: D/D | C7: Bernasconi | D7: 0.51 | E7: Ahanor | G7: 0.49
A8: Bologna | B8: D/D | C8: Zortea | D8: 0.51 | E8: Holm | G8: 0.49
A9: Bologna | B9: C/C | C9: Bernardeschi | D9: 0.6 | E9: Odgaard | G9: 0.4
A10: Bologna | B10: C/C | C10: Pobega | D10: 0.55 | E10: Moro N. | G10: 0.45
A11: Bologna | B11: A/A | C11: Dovbyk | D11: 0.55 | E11: Piccoli | G11: 0.45
A12: Cagliari | B12: D/C | C12: Mina | D12: 0.51 | E12: Deiola | G12: 0.49
A13: Cagliari | B13: D/D | C13: Zè Pedro | D13: 0.55 | E13: Zappa | G13: 0.45
A14: Cagliari | B14: A/A/A | C14: Kevin Carlos | D14: 0.34 | E14: Mendy P. | F14: Borrelli | G14: 0.33
A15: Como | B15: C/C | C15: Perrone | D15: 0.6 | E15: Milla | G15: 0.4
A16: Como | B16: A/C | C16: Diao | D16: 0.6 | E16: Rodriguez Je. | G16: 0.4
A17: Como | B17: D/D | C17: Couto | D17: 0.51 | E17: Smolcic I. | G17: 0.49
A18: Como | B18: D/D | C18: Valle | D18: 0.51 | E18: Kaiki | G18: 0.49
A19: Como | B19: D/D | C19: Ramon | D19: 0.55 | E19: Kempf | G19: 0.45
A20: Fiorentina | B20: D/D | C20: Jimenez A. | D20: 0.51 | E20: Joao Mario | G20: 0.49
A21: Fiorentina | B21: D/D | C21: Viery | D21: 0.51 | E21: Ranieri L. | G21: 0.49
A22: Fiorentina | B22: C/C | C22: Ndour | D22: 0.51 | E22: Gudmundsson A. | G22: 0.49
A23: Fiorentina | B23: A/A | C23: Kean | D23: 0.6 | E23: Pellegrino M. | G23: 0.4
A24: Frosinone | B24: P/P | C24: Palmisani | D24: 0.51 | E24: Desplanches | G24: 0.49
A25: Frosinone | B25: A/C | C25: Kvernadze | D25: 0.51 | E25: Zerbin | G25: 0.49
A26: Frosinone | B26: D/D | C26: Monterisi | D26: 0.51 | E26: Calvani | G26: 0.49
A27: Frosinone | B27: C/C | C27: Masini | E27: Koutsoupias
A28: Frosinone | B28: C/C | C28: Grillitsch | D28: 0.55 | E28: Calò | G28: 0.45
A29: Genoa | B29: A/C | C29: Vitinha O. | D29: 0.51 | E29: Meichtry | G29: 0.49
A30: Genoa | B30: C/C | C30: Baldanzi | D30: 0.51 | E30: Traorè Hj. | G30: 0.49
A31: Genoa | B31: D/C | C31: Mitaj | D31: 0.51 | E31: Ellertsson | G31: 0.49
A32: Inter | B32: C/C | C32: Zielinski | D32: 0.55 | E32: Sucic P. | G32: 0.45
A33: Inter | B33: C/C | C33: Diouf | D33: 0.51 | E33: Luis Henrique | G33: 0.49
A34: Inter | B34: P/P | C34: Martinez Jo. | D34: 0.55 | E34: Provedel | G34: 0.45
A35: Inter | B35: D/D | C35: Stones | D35: 0.55 | E35: Bisseck | G35: 0.45
A36: Inter | B36: D/C | C36: Spence | D36: 0.6 | E36: Diouf | G36: 0.4
A37: Juventus | B37: C/C | C37: Alajbegovic | D37: 0.51 | E37: Conceicao | G37: 0.49
A38: Juventus | B38: D/D | C38: Lucumì | D38: 0.6 | E38: Kelly L. | G38: 0.4
A39: Lazio | B39: C/C | C39: Rovella | D39: 0.55 | E39: Cataldi | G39: 0.45
... A71: Venezia | B71: D/D | C71: Moreno M. | D71: 0.51 | E71: Halhal | G71: 0.49

Sheet Piazzati
A1: Squadra | B1: Tipo | C1: Ordine | D1: Ruolo | E1: Giocatore
A2: Atalanta | B2: Rigori | C2: 1 | D2: A | E2: Scamacca
A3: Atalanta | B3: Rigori | C3: 2 | D3: C | E3: Samardzic
A4: Atalanta | B4: Rigori | C4: 3 | D4: C | E4: Ederson D.S.
A5: Atalanta | B5: Punizioni | C5: 1 | D5: C | E5: Samardzic
A6: Atalanta | B6: Punizioni | C6: 2 | D6: C | E6: Gaetano
A7: Atalanta | B7: Calci d'angolo | C7: 1 | D7: C | E7: Samardzic
A8: Atalanta | B8: Calci d'angolo | C8: 2 | D8: C | E8: Gaetano
A9: Atalanta | B9: Calci d'angolo | C9: 3 | D9: D | E9: Bernasconi
A10: Bologna | B10: Rigori | C10: 1 | D10: C | E10: Orsolini
A11: Bologna | B11: Rigori | C11: 2 | D11: A | E11: Dovbyk
A12: Bologna | B12: Rigori | C12: 3 | D12: C | E12: Bernardeschi
A13: Bologna | B13: Punizioni | C13: 1 | D13: C | E13: Orsolini
... A160: Venezia | B160: Calci d'angolo | C160: 3 | D160: C | E160: Basic

Sheet Note
A1: Squadra | B1: Categoria | C1: Ruolo | D1: Giocatore | E1: Nota
A2: Atalanta | B2: Valorizzato | C2: D | D2: Scalvini | E2: Difesa di Sarri solida
A3: Atalanta | B3: Valorizzato | C3: A | D3: Raspadori | E3: Adattabile anche al centro
A4: Atalanta | B4: Valorizzato | C4: A | D4: Raspadori | E4: Esterni di Sarri prolifici
A5: Atalanta | B5: Valorizzato | C5: A | D5: Raspadori | E5: Rotazioni elevate nel suo ruolo
A6: Atalanta | B6: Penalizzato | C6: C | D6: De Roon | E6: Con Sarri posizionamento più arretrato
A7: Atalanta | B7: Penalizzato | C7: D | D7: Kossounou | E7: Parte indietro nelle gerarchie del mister
A8: Atalanta | B8: Nome nascosto | C8: C | D8: Samardzic | E8: Sarri può rigenerarlo
A9: Atalanta | B9: Giovane | C9: D | D9: Bernasconi | E9: Esterno equilibrato in entrambe le fasi
A10: Bologna | B10: Valorizzato | C10: C | D10: Rowe | E10: Caratteristiche in linea con gli esterni del mister
A11: Bologna | B11: Valorizzato | C11: C | D11: Rowe | E11: Poca concorrenza
A12: Bologna | B12: Valorizzato | C12: C | D12: Orsolini | E12: Perno offensivo del gioco del mister
A13: Bologna | B13: Valorizzato | C13: C | D13: Orsolini | E13: Maggiore minutaggio rispetto all'anno scorso
A14: Bologna | B14: Penalizzato | E14: Parte indietro nelle gerarchie
A15: Bologna | B15: Penalizzato | C15: D | D15: Lucumì | E15: Potrebbe soffrire un sistema di gioco elaborato
A16: Bologna | B16: Nome nascosto | C16: C | D16: Bernardeschi | E16: Duttile tatticamente. Usato in più ruoli.
A17: Bologna | B17: Giovane | C17: C | D17: Dominguez B. | E17: Tanta concorrenza sugli esterni
A18: Cagliari | B18: Valorizzato | C18: D | D18: Obert | E18: Buoni cross anche dai piazzati
A19: Cagliari | B19: Valorizzato | C19: D | D19: Obert | E19: Utilizzato in più posizioni nella fase difensiva
A20: Cagliari | B20: Valorizzato | C20: C | D20: Fazzini | E20: Voluto fortemente da Pisacane
A21: Cagliari | B21: Valorizzato | C21: C | D21: Fazzini | E21: Propensione al bonus
A22: Cagliari | B22: Valorizzato | C22: C | D22: Fazzini | E22: Dubbio su integrità fisica
A23: Cagliari | B23: Penalizzato | C23: D | D23: Zappa | E23: Sistema molto difensivo potrebbe penalizzarlo
A24: Cagliari | B24: Nome nascosto | C24: C | D24: Romano | E24: Forte nelle transizioni offensive
A25: Cagliari | B25: Giovane | C25: A | D25: Mendy P. | E25: Può facilmente ritagliarsi spazio
A26: Como | B26: Valorizzato | C26: C | D26: Da Cunha | E26: Duttile Tatticamente
... A156: Venezia | B156: Giovane | C156: C | D156: Dagasso | E156: Bravo in fase di interdizione e di inserimento

Sheet PuntiChiave
A1: Squadra | B1: Allenatore | C1: # | D1: Punto chiave
A2: Atalanta | B2: M. Sarri | C2: 1 | D2: Valorizzazione esterni d'attacco
A3: Atalanta | B3: M. Sarri | C3: 2 | D3: Solidità difensiva
A4: Atalanta | B4: M. Sarri | C4: 3 | D4: Scarso impiego del turnover
A5: Atalanta | B5: M. Sarri | C5: 4 | D5: Scarsa libertà ai terzini
A6: Bologna | B6: D. Tedesco | C6: 1 | D6: Valorizzazione esterni d'attacco
A7: Bologna | B7: D. Tedesco | C7: 2 | D7: Adattamento Serie A
A8: Bologna | B8: D. Tedesco | C8: 3 | D8: Sistema di gioco molto elaborato
A9: Cagliari | B9: F. Pisacane | C9: 1 | D9: Valorizzazione giovani
A10: Cagliari | B10: F. Pisacane | C10: 2 | D10: Solidità difensiva
A11: Cagliari | B11: F. Pisacane | C11: 3 | D11: Attacco poco prolifico
A12: Como | B12: C. Fabregas | C12: 1 | D12: Valorizzazione giovani
A13: Como | B13: C. Fabregas | C13: 2 | D13: Solidità difensiva
... A63: Venezia | B63: G. Stroppa | C63: 3 | D63: Interpreti del suo gioco potrebbero faticare in serie A
